<!-- Copyright 2024 DeepMind Technologies Limited

     Licensed under the Apache License, Version 2.0 (the "License");
     you may not use this file except in compliance with the License.
     You may obtain a copy of the License at

         http://www.apache.org/licenses/LICENSE-2.0

     Unless required by applicable law or agreed to in writing, software
     distributed under the License is distributed on an "AS IS" BASIS,
     WITHOUT WARRANTIES OR CONDITIONS OF ANY KIND, either express or implied.
     See the License for the specific language governing permissions and
     limitations under the License.
-->

<mujoco model="Gripper">
  <compiler meshdir="asset" texturedir="asset"/>

  <statistic meansize=".05"/>

  <visual>
    <rgba haze="0.15 0.25 0.35 1"/>
    <quality shadowsize="4096"/>
    <map stiffness="700" shadowscale="0.5" fogstart="1" fogend="15" zfar="40" haze="1"/>
  </visual>

  <asset>
    <texture type="skybox" builtin="gradient" rgb1="0.3 0.5 0.7" rgb2="0 0 0" width="512" height="512"/>
    <texture name="texplane" type="2d" builtin="checker" rgb1=".2 .3 .4" rgb2=".1 0.15 0.2"
      width="512" height="512" mark="cross" markrgb=".8 .8 .8"/>

    <material name="matplane" reflectance="0.3" texture="texplane" texrepeat="10 10" texuniform="true"/>
  </asset>

  <option cone="elliptic" impratio="10" integrator="implicitfast"/>

  <worldbody>
    <light diffuse=".4 .4 .4" specular="0.1 0.1 0.1" pos="0 0 2.0" dir="0 0 -1" castshadow="false"/>
    <light directional="true" diffuse=".8 .8 .8" specular="0.2 0.2 0.2" pos="0 0 4" dir="0 0 -1"/>

    <geom name="ground" type="plane" size="0 0 1" pos="0 0 0" quat="1 0 0 0" material="matplane" condim="1"/>
  
    <body name="hand" pos="0 0 .37">
      <joint name="lift" type="slide" range="0 1"/>
      <geom type="box" size=".2 .1 .05" rgba=".2 .2 .2 1"/>
      <body name="right_gripper">
        <joint name="right" type="slide" axis="-1 0 0"/>
        <geom type="box" size=".02 .1 .15" pos=".18 0 -.2" rgba=".2 .2 .2 1"/>
      </body>
      <body name="left_gripper">
        <joint name="left" type="slide" axis="1 0 0"/>
        <geom type="box" size=".02 .1 .15" pos="-.18 0 -.2" rgba=".2 .2 .2 1"/>
      </body>
    </body>
    <flexcomp name="softcube" type="box" count="6 11 11" spacing=".02 .02 .02" pos="0 0 .1" dim="3" radius="0.01" rgba=".5 .5 0 1" dof="trilinear" mass="4">
      <elasticity young="1e5" poisson="0.3" damping="1e-3"/>
      <contact internal="false" selfcollide="none"/>
      <edge equality="true"/>
    </flexcomp>
  </worldbody>

  <equality>
    <joint joint1="right" joint2="left"/>
  </equality>

  <tendon>
    <fixed name="grasp">
      <joint joint="right" coef="1"/>
      <joint joint="left" coef="1"/>
    </fixed>
  </tendon>

  <actuator>
    <position name="lift" joint="lift" kp="600" dampratio="1" ctrlrange="0 1"/>
    <position name="grasp" tendon="grasp" kp="200" dampratio="1" ctrlrange="0 1"/>
  </actuator>

  <sensor>
    <contact name="cube_contact" subtree1="hand" num="1" data="found force torque dist pos normal tangent"/>
  </sensor>

</mujoco>
